Tue, 04 Sep 2018 16:36:46 connectionpool.py[line:208] DEBUG Starting new HTTP connection (1): api.zkteco.com
Tue, 04 Sep 2018 16:36:46 HttpPost.py[line:58] INFO HTTPConnectionPool(host='api.zkteco.com', port=80): Max retries exceeded with url: /admin/a.html (Caused by NewConnectionError('<urllib3.connection.HTTPConnection object at 0x000001CD8D0D7F60>: Failed to establish a new connection: [Errno 11001] getaddrinfo failed',))
Tue, 04 Sep 2018 16:36:46 connectionpool.py[line:208] DEBUG Starting new HTTP connection (1): api.zkteco.com
Tue, 04 Sep 2018 16:36:46 HttpPost.py[line:58] INFO HTTPConnectionPool(host='api.zkteco.com', port=80): Max retries exceeded with url: /admin/a.html (Caused by NewConnectionError('<urllib3.connection.HTTPConnection object at 0x000001CD8D0D7DA0>: Failed to establish a new connection: [Errno 11001] getaddrinfo failed',))
Tue, 04 Sep 2018 16:36:46 connectionpool.py[line:208] DEBUG Starting new HTTP connection (1): api.zkteco.com
Tue, 04 Sep 2018 16:36:46 HttpPost.py[line:58] INFO HTTPConnectionPool(host='api.zkteco.com', port=80): Max retries exceeded with url: /admin/a.html (Caused by NewConnectionError('<urllib3.connection.HTTPConnection object at 0x000001CD8D0D75C0>: Failed to establish a new connection: [Errno 11001] getaddrinfo failed',))
Tue, 04 Sep 2018 16:36:48 connectionpool.py[line:208] DEBUG Starting new HTTP connection (1): api.zkteco.com
Tue, 04 Sep 2018 16:36:48 HttpPost.py[line:58] INFO HTTPConnectionPool(host='api.zkteco.com', port=80): Max retries exceeded with url: /admin/a.html (Caused by NewConnectionError('<urllib3.connection.HTTPConnection object at 0x000001CD8D0D7F60>: Failed to establish a new connection: [Errno 11001] getaddrinfo failed',))
Tue, 04 Sep 2018 16:36:48 connectionpool.py[line:208] DEBUG Starting new HTTP connection (1): api.zkteco.com
Tue, 04 Sep 2018 16:36:48 HttpPost.py[line:58] INFO HTTPConnectionPool(host='api.zkteco.com', port=80): Max retries exceeded with url: /admin/a.html (Caused by NewConnectionError('<urllib3.connection.HTTPConnection object at 0x000001CD8D0D7DA0>: Failed to establish a new connection: [Errno 11001] getaddrinfo failed',))
Tue, 04 Sep 2018 16:36:48 connectionpool.py[line:208] DEBUG Starting new HTTP connection (1): api.zkteco.com
Tue, 04 Sep 2018 16:36:48 HttpPost.py[line:58] INFO HTTPConnectionPool(host='api.zkteco.com', port=80): Max retries exceeded with url: /admin/a.html (Caused by NewConnectionError('<urllib3.connection.HTTPConnection object at 0x000001CD8D0D75C0>: Failed to establish a new connection: [Errno 11001] getaddrinfo failed',))
Tue, 04 Sep 2018 16:36:50 connectionpool.py[line:208] DEBUG Starting new HTTP connection (1): api.zkteco.com
Tue, 04 Sep 2018 16:36:50 HttpPost.py[line:58] INFO HTTPConnectionPool(host='api.zkteco.com', port=80): Max retries exceeded with url: /admin/a.html (Caused by NewConnectionError('<urllib3.connection.HTTPConnection object at 0x000001CD8D0D7F60>: Failed to establish a new connection: [Errno 11001] getaddrinfo failed',))
Tue, 04 Sep 2018 16:36:50 connectionpool.py[line:208] DEBUG Starting new HTTP connection (1): api.zkteco.com
Tue, 04 Sep 2018 16:36:50 HttpPost.py[line:58] INFO HTTPConnectionPool(host='api.zkteco.com', port=80): Max retries exceeded with url: /admin/a.html (Caused by NewConnectionError('<urllib3.connection.HTTPConnection object at 0x000001CD8D0D7DA0>: Failed to establish a new connection: [Errno 11001] getaddrinfo failed',))
Tue, 04 Sep 2018 16:36:50 connectionpool.py[line:208] DEBUG Starting new HTTP connection (1): api.zkteco.com
Tue, 04 Sep 2018 16:36:50 HttpPost.py[line:58] INFO HTTPConnectionPool(host='api.zkteco.com', port=80): Max retries exceeded with url: /admin/a.html (Caused by NewConnectionError('<urllib3.connection.HTTPConnection object at 0x000001CD8D0D75C0>: Failed to establish a new connection: [Errno 11001] getaddrinfo failed',))
Tue, 04 Sep 2018 16:36:52 connectionpool.py[line:208] DEBUG Starting new HTTP connection (1): api.zkteco.com
Tue, 04 Sep 2018 16:36:52 HttpPost.py[line:58] INFO HTTPConnectionPool(host='api.zkteco.com', port=80): Max retries exceeded with url: /admin/a.html (Caused by NewConnectionError('<urllib3.connection.HTTPConnection object at 0x000001CD8D11C390>: Failed to establish a new connection: [Errno 11001] getaddrinfo failed',))
Tue, 04 Sep 2018 16:36:52 connectionpool.py[line:208] DEBUG Starting new HTTP connection (1): api.zkteco.com
Tue, 04 Sep 2018 16:36:52 HttpPost.py[line:58] INFO HTTPConnectionPool(host='api.zkteco.com', port=80): Max retries exceeded with url: /admin/a.html (Caused by NewConnectionError('<urllib3.connection.HTTPConnection object at 0x000001CD8D11C2E8>: Failed to establish a new connection: [Errno 11001] getaddrinfo failed',))
Tue, 04 Sep 2018 16:36:52 connectionpool.py[line:208] DEBUG Starting new HTTP connection (1): api.zkteco.com
Tue, 04 Sep 2018 16:36:52 HttpPost.py[line:58] INFO HTTPConnectionPool(host='api.zkteco.com', port=80): Max retries exceeded with url: /admin/a.html (Caused by NewConnectionError('<urllib3.connection.HTTPConnection object at 0x000001CD8D11C438>: Failed to establish a new connection: [Errno 11001] getaddrinfo failed',))
Tue, 04 Sep 2018 16:36:54 connectionpool.py[line:208] DEBUG Starting new HTTP connection (1): api.zkteco.com
Tue, 04 Sep 2018 16:36:54 HttpPost.py[line:58] INFO HTTPConnectionPool(host='api.zkteco.com', port=80): Max retries exceeded with url: /admin/a.html (Caused by NewConnectionError('<urllib3.connection.HTTPConnection object at 0x000001CD8D11C2B0>: Failed to establish a new connection: [Errno 11001] getaddrinfo failed',))
Tue, 04 Sep 2018 16:36:54 connectionpool.py[line:208] DEBUG Starting new HTTP connection (1): api.zkteco.com
Tue, 04 Sep 2018 16:36:54 HttpPost.py[line:58] INFO HTTPConnectionPool(host='api.zkteco.com', port=80): Max retries exceeded with url: /admin/a.html (Caused by NewConnectionError('<urllib3.connection.HTTPConnection object at 0x000001CD8D11C400>: Failed to establish a new connection: [Errno 11001] getaddrinfo failed',))
Tue, 04 Sep 2018 16:36:54 connectionpool.py[line:208] DEBUG Starting new HTTP connection (1): api.zkteco.com
Tue, 04 Sep 2018 16:36:54 HttpPost.py[line:58] INFO HTTPConnectionPool(host='api.zkteco.com', port=80): Max retries exceeded with url: /admin/a.html (Caused by NewConnectionError('<urllib3.connection.HTTPConnection object at 0x000001CD8D11C128>: Failed to establish a new connection: [Errno 11001] getaddrinfo failed',))
